文档写到现在也没有提及到错误信息，但是你也能从之前的例子中看到一些错误的定义和捕获，python至少有两种可区分的错误：语法错误(error)和程序异常(exception)

### 8.1. 语法错误(Syntax Errors)
语法，也就是为人所知的解析错误，也是你在学习Python过程中抱怨最多的事情

```
>>> while True print('Hello world')
  File "<stdin>", line 1
    while True print('Hello world')
                   ^
SyntaxError: invalid syntax
```
解析器会将出错的行重新打印出来，并且使用一个小小的箭头指向最初检测到错误的位置，错误是发生在(至少检测是这样)箭头指向位置之前，在上述例子中，检测到的错误发生在print()，是因为在print之前缺少冒号，文件名和行号也打印了，这样就能精确定位错误，方便查找错误
### 8.2 异常(Exception)
即使语句和表达式的语法是正确的，也可能在执行的时候产生一个错误，在执行期间检测到的错误叫做异常，当然异常也不是百分百会让程序奔溃，你将很快学会如何在python编程中处理它们。大部分的异常不是由程序控制的，但是，异常结果都是如下所示的模式：

```
>>> 10 * (1/0)
Traceback (most recent call last):
  File "<stdin>", line 1, in <module>
ZeroDivisionError: division by zero
>>> 4 + spam*3
Traceback (most recent call last):
  File "<stdin>", line 1, in <module>
NameError: name 'spam' is not defined
>>> '2' + 2
Traceback (most recent call last):
  File "<stdin>", line 1, in <module>
TypeError: Can't convert 'int' object to str implicitly
```
最后一行的错误信息会指明发生了什么， 异常的来源形形色色，打印异常信息的时候也会带上异常的类型，例子中的异常类型就是ZeroDivisionError，NameError和TypeError。表示异常类型的字符串和在python内置异常定义的名称是一致的，这对于所有的内置异常来说是正确的，但是对于用户定义的异常来说就有可能不太对(虽然这是公约)。标准的异常名称是内置的标识符(不包括预留字)

剩下的信息是基于异常类型的详细信息以及是什么造成异常的

### 8.3 异常处理
对于可能发生的已知异常可以进行处理，请看下面的例子，要求用户输入一个整数，当用户输入一个非法的整数时，则捕获该异常，并且允许用户终端程序（使用Control-C或者任意的操作系统支持的方式），注意： 用户生成的中断在程序中表示的抛出一个叫做 KeyboardInterrupt的异常

```
>>> while True:
...     try:
...         x = int(input('Please enter a number: '))
...         break
...     except ValueError:
...         print('Oops! That was no valid number. Try again...')
...
```
try语句工作流程如下：
* 首先， try子句(在try和except之间的语句)已经执行
* 如果没有异常产生，那么except子句就不执行并且结束try语句
* 当执行try字句时发生了异常，try语句剩下的代码不会执行。如何该异常的类型是except后面声明的异常类型，则会执行except中的字句。并且会执行try语句后代码
* 如何异常发生了并且和except声明的异常类型并不匹配，那么就会跳出当前的try语句，并把异常上传给上一级，如果没有找到处理该异常类型的代码，这就是个未处理异常并且解释器会终止执行程序，并输出带有该异常的如上类似的信息

一个try语句可能不止一个except的子句，针对性的处理不同的异常，但是最多只会有一个异常处理会被执行，处理器只会处理和try中发生的一致的异常，而不会处理相同try语句下的其它异常处理。一个except子句可能命名了多个异常并且这些异常是一个使用括号括起来的元组，如下所示：
```
... except (RuntimeError, TypeError, NameError):
...     pass 
```

如果一个类是except的子句中的异常类的相同类或者派生类，则该except异常捕获会捕获该异常(如果是相反的情况，该类是except子句异常类的基类，则无法捕获该异常)， 例如，下面的代码将会按顺序打印出B、C、D
```
>>> class B(Exception):
...     pass
...
>>> class C(B):
...     pass
...
>>> class D(C):
...     pass
...
>>>
>>> for cls in [B, C, D]:
...     try:
...             raise cls()
...     except D:
...             print('D')
...     except C:
...             print('C')
...     except B:
...             print('B')
...
```
请注意： 如果这个except子句是相反的结构(先处理的是B异常)，那么它将打印的是B, B, B ——第一个except子句将会触发

最后一个except的子句可能会忽略exception的名称，以此作为通配符。当然使用的时候要异常小心，因为这样做很容易掩饰一个真实的编程错误，这也经常用于打印出一个错误信息以及重新抛出该异常(使得调用者可以捕获并处理该异常信息)

```
>>> import sys
>>>
>>> try:
...     f = open('myfile.txt')
...     s = f.readline()
...     i = int(s.strip())
... except OSError as error:
...     print('OS error: {0}'.format(err))
... except ValueError:
...     print('Could not convert data to an integer.')
... except:
...     print('Unexcepted error: {0}', sys.exc_info()[0])
...     raise
```

try...except语句还有个可选的else子句， 但是必须放在所有的except子句的下面，这对于try语句没有出现异常则代码继续运行很有帮助，如下所示：
```
for arg in sys.argv[1:]:
    try:
        f = open(arg, 'r')
    except OSError:
        print('cannot open', arg)
    else:
        print(arg, 'has', len(f.readlines()), 'lines')
        f.close()
```

使用else字句要比在try子句中增加额外的代码要好很多，因为这避免了突然抛出了异常并且该异常没有被try...except捕获

当发生异常时，异常会生成与之相关的值，也就是所谓的异常参数。该参数的的展示和类型取决于异常的类型

except字句会在异常名称之后定义一个变量，这个变量指向的是带有参数的异常实例，该参数存储在instance.args。为了方面，类型实例定义了__str__()函数，因此这些参数的打印不需要引用.args。如果想要抛出一个异常并且添加一些属性必须先实例化该异常。

```
>>> try:
...     raise Exception('spam', 'eggs')
... except Exception as inst:
...     print(type(inst))    # the exception instance
...     print(inst.args)     # arguments stored in .args
...     print(inst)          # __str__ allows args to be printed directly,
...                          # but may be overridden in exception subclasses
...     x, y = inst.args     # unpack args
...     print('x =', x)
...     print('y =', y)
...
<class 'Exception'>
('spam', 'eggs')
('spam', 'eggs')
x = spam
y = eggs
```
如果一个异常有参数，如果未处理异常的话，这些参数会作为异常信息的最后信息打印出来。

异常处理程序并不仅仅处理直接在try子句中发生的异常，而且会处理在子句中调用方法发生的异常，如下所示：
```
>>> def this_fails():
...     x = 1/0
...
>>> try:
...     this_fails()
... except ZeroDivisionError as err:
...     print('Handling run-time error:', err)
...
Handling run-time error: division by zero
```

### 8.4. 抛出异常
raise语句可以让程序强制抛出一个指定的异常，如下所示：
```
>>> raise NameError('HiThere')
Traceback (most recent call last):
  File "<stdin>", line 1, in <module>
NameError: HiThere
```
传递给raise的唯一参数表明已抛出的异常，这个参数要么是异常的实例，要么就是异常类(该类是Exception的派生类)，如果一个异常类被传递，这个异常将会调用它的无参构造函数从而被隐式实例化。
```
raise ValueError  # shorthand for 'raise ValueError()'
```

如果你需要决定是否抛出一个异常，并且不想处理该异常，有一种简单的抛出异常模式可以  重新抛出该异常。如下所示：
```
>>> try:
...     raise NameError('HiThere')
... except NameError:
...     print('An exception flew by'!)
  File "<stdin>", line 4
    print('An exception flew by'!)
                                ^
SyntaxError: invalid syntax
>>> try:
...     raise NameError('HiThere')
... except NameError:
...     print('An exception flew by!')
...     raise
...
An exception flew by!
Traceback (most recent call last):
  File "<stdin>", line 2, in <module>
NameError: HiThere
```

### 8.5用户定义异常
程序可以通过创建一个新的异常类来实现自己定义异常，但是这些异常必须是Exception的衍生类，无论是直接的还是间接的。

异常类可以像其他类一样处理任何事情，但是通常是简单就好，异常类常常是提供了一些属性值，使得处理器能捕获到异常的错误信息。当创建一个模块时，该模块需要抛出多个不同的异常，普遍的做法是由该模块创建一个基础的异常类，然后创建多个子类来定义不同的异常类以应对不同的错误情况。

```
class Error(Exception):
    """Base class for exceptions in this modules"""
    pass
 
class InputError(Error):
    """ Exception raised for error inn the input
    
    attributes:
        expression -- input expression in which the error occurred
        message -- explanation of the error
    """
        
        def __init__(self, expression, message):
            self.expression = expression
            self.message = message
            
class TransitionError(Error):
    """Raised when an operation attempts a state transition that's not allowed
    
    Attributes: 
        previous -- state at beginning of transition
        next -- attempts new state
        message -- explanation of why the specific transition is not allowed
    """
    
    def __init__(self, previous, next, message):
        self.previous = previous
        self.next = next
        self.message = message
```
大多数的异常定义的异常命名都是为以"Error"结尾，和标准的异常命名类似

很多的标准模块都会定义一些异常，这些异常就是在他们定义的方法中可能出现的错误

### 定义清理动作
try子句中有一个为了清理动作而使用的子句选项，这个子句在任何情况下都会被执行，如下所示：
```
>>> try:
...     raise KeyboardInterrupt
... finally:
...     print('Goodbye, world!')
...
Goodbye, world!
Traceback (most recent call last):
  File "<stdin>", line 2, in <module>
KeyboardInterrupt
```
finally子句总是在离开try子句之前被执行，不管有没有发生异常，当try子句中发生了异常而又没被捕获到(或者异常发生在except或者else子句中)，重新抛出的语句是在执行完finally子句才抛出的。就算是try子句使用break、continue或者return语句离开try子句，finally子句依然会被执行。下面是一个更为复杂的例子：
```
>>> def divide(x, y):
...     try:
...         result = x / y
...     except ZeroDivisionError:
...         print('division by zero!')
...     else:
...         print('result is {0}'.format(result))
...     finally:
...         print('excuting finally clause')
...
>>> divide(2, 1)
result is 2.0
excuting finally clause
>>> divide(2, 0)
division by zero!
excuting finally clause
>>> divide('2', 1)
excuting finally clause
Traceback (most recent call last):
  File "<stdin>", line 1, in <module>
  File "<stdin>", line 3, in divide
TypeError: unsupported operand type(s) for /: 'str' and 'int'
```

正如你所看到的那样， finally语句在任何情况下都会被执行，两个字符串想除的类型错误并没有被except子句捕获到，所以在执行完finally子句以后再向上抛出

在实际的应用程序中，finally在释放外部的资源方面很有用处(例如文件或者网络连接)，无论这个资源的使用是否成功，都会被释放。

### 8.7 预定义的清理动作
当一个对象不再使用时，一些对象会定义标准的清理动作来清理这些对象，无论程序是否成功的使用该对象，如下为一个打开一个文件并将内容输出到屏幕的例子：
```
>>> for line in open('myfile.txt'):
...     print(line, end="")
```

这段代码的问题是当这段代码执行完成后，文件依然会在不确定的时间段内打开着。这不仅仅是一个简单脚本会出现的问题，而是可能会成为一个大型应用程序的大问题。with语句可以确保类似文件的对象总是能够及时并且正确的被清理。
```
>>> with open('myfile.txt') as f:
...     for line in f:
...         print(line, end='')
```
当这个语句执行完时，文件f总是会被关闭，及时在执行这些代码出现问题时，类似文件的对象在它们的文档中都会提供预定义的清理动作。
